<?xml version="1.0"?>
<robot xmlns:xacro="http://www.ros.org/wiki/xacro">

  <joint name="left_wrist_roll_joint_X4" type="revolute">
    <origin xyz="-1.66533e-16 0.033 -0.0565" rpy="1.5708 -0.174533 1.69056e-18"/>
    <parent link="urdf_l_lower_forearm_assembly"/>
    <child link="urdf_l_wrist_assembly"/>
    <axis xyz="0 0 1"/>
    <limit effort="10" velocity="10" lower="-1.74533" upper="1.39626"/>
  </joint>
  <joint name="left_wrist_yaw_joint_X4" type="revolute">
    <origin xyz="1.38778e-17 -0.168 0.04" rpy="-1.5708 -1.5708 0"/>
    <parent link="urdf_l_upper_forearm_assembly"/>
    <child link="urdf_l_lower_forearm_assembly"/>
    <axis xyz="0 0 1"/>
    <limit effort="10" velocity="10" lower="-2.35619" upper="2.35619"/>
  </joint>
  <joint name="left_elbow_pitch_joint_X6" type="revolute">
    <origin xyz="-0.04 -6.93889e-18 -0.065" rpy="1.5708 -2.10491e-17 1.5708"/>
    <parent link="urdf_l_elbow_assembly"/>
    <child link="urdf_l_upper_forearm_assembly"/>
    <axis xyz="0 0 1"/>
    <limit effort="10" velocity="10" lower="-1.5708" upper="1.5708"/>
  </joint>
  <joint name="left_shoulder_yaw_joint_X4" type="revolute">
    <origin xyz="1.38778e-16 -0.17 0.046" rpy="-1.5708 -6.32981e-16 -1.98615e-16"/>
    <parent link="urdf_l_upper_arm_assembly"/>
    <child link="urdf_l_elbow_assembly"/>
    <axis xyz="0 0 1"/>
    <limit effort="10" velocity="10" lower="-2.35619" upper="2.35619"/>
  </joint>
  <joint name="left_shoulder_roll_joint_X6" type="revolute">
    <origin xyz="0.046 -5.55112e-17 -0.07" rpy="1.5708 -1.39626 -1.5708"/>
    <parent link="urdf_l_shoulder_assembly"/>
    <child link="urdf_l_upper_arm_assembly"/>
    <axis xyz="0 0 1"/>
    <limit effort="10" velocity="10" lower="-1.39626" upper="1.74533"/>
  </joint>
  <joint name="left_shoulder_pitch_joint_X6" type="revolute">
    <origin xyz="-0.162498 -3.95689e-06 -0.421" rpy="-1.5708 1.2642e-15 -1.5708"/>
    <parent link="urdf_simplified_torso_sub_assembly"/>
    <child link="urdf_l_shoulder_assembly"/>
    <axis xyz="0 0 1"/>
    <limit effort="10" velocity="10" lower="-1.5708" upper="3.14159"/>
  </joint>
  <joint name="right_wrist_roll_joint_X4" type="revolute">
    <origin xyz="-3.88578e-16 0.033 -0.0565" rpy="1.5708 0.174533 1.00188e-18"/>
    <parent link="urdf_r_lower_forearm_assembly"/>
    <child link="urdf_r_wrist_assembly"/>
    <axis xyz="0 0 1"/>
    <limit effort="10" velocity="10" lower="-1.39626" upper="1.74533"/>
  </joint>
  <joint name="right_wrist_yaw_joint_X4" type="revolute">
    <origin xyz="4.85723e-17 0.168 0.04" rpy="1.5708 1.5708 0"/>
    <parent link="urdf_r_upper_forearm_assembly"/>
    <child link="urdf_r_lower_forearm_assembly"/>
    <axis xyz="0 0 1"/>
    <limit effort="10" velocity="10" lower="-2.35619" upper="2.35619"/>
  </joint>
  <joint name="right_elbow_pitch_joint_X6" type="revolute">
    <origin xyz="0.04 8.32667e-17 -0.065" rpy="-1.5708 -4.75872e-16 1.5708"/>
    <parent link="urdf_r_elbow_assembly"/>
    <child link="urdf_r_upper_forearm_assembly"/>
    <axis xyz="0 0 1"/>
    <limit effort="10" velocity="10" lower="-1.5708" upper="1.5708"/>
  </joint>
  <joint name="right_shoulder_yaw_joint_X4" type="revolute">
    <origin xyz="0 -0.17 0.046" rpy="-1.5708 4.66207e-17 -1.0175e-15"/>
    <parent link="urdf_r_upper_arm_assembly"/>
    <child link="urdf_r_elbow_assembly"/>
    <axis xyz="0 0 1"/>
    <limit effort="10" velocity="10" lower="-2.35619" upper="2.35619"/>
  </joint>
  <joint name="right_shoulder_roll_joint_X6" type="revolute">
    <origin xyz="0.046 -2.77556e-17 -0.07" rpy="1.5708 1.39626 -1.5708"/>
    <parent link="urdf_r_shoulder_assembly"/>
    <child link="urdf_r_upper_arm_assembly"/>
    <axis xyz="0 0 1"/>
    <limit effort="10" velocity="10" lower="-1.74533" upper="1.39626"/>
  </joint>
  <joint name="right_shoulder_pitch_joint_X6" type="revolute">
    <origin xyz="0.162502 -3.95689e-06 -0.421" rpy="1.5708 -1.25563e-17 -1.5708"/>
    <parent link="urdf_simplified_torso_sub_assembly"/>
    <child link="urdf_r_shoulder_assembly"/>
    <axis xyz="0 0 1"/>
    <limit effort="10" velocity="10" lower="-3.14159" upper="1.5708"/>
  </joint>
  <joint name="waist_yaw_joint" type="fixed">
    <origin xyz="0.000699067 0.0333466 -0.29826" rpy="3.14159 2.72165e-16 4.32987e-15"/>
    <parent link="urdf_base"/>
    <child link="urdf_simplified_torso_sub_assembly"/>
    <axis xyz="0 0 1"/>
    <limit effort="10" velocity="10" lower="-1.5708" upper="1.5708"/>
  </joint>
  
  <!-- Left leg: single box replacing 6 links + 12 joints -->
  <joint name="left_leg_joint" type="fixed">
    <origin xyz="-0.175 0.055 -0.858" rpy="0 0 0"/>
    <parent link="urdf_base"/>
    <child link="left_leg_link"/>
  </joint>

  <!-- Right leg: single box replacing 6 links + 12 joints -->
  <joint name="right_leg_joint" type="fixed">
    <origin xyz="0.177 0.058 -0.858" rpy="0 0 0"/>
    <parent link="urdf_base"/>
    <child link="right_leg_link"/>
  </joint>

</robot>
